Workbook

Sheet 2020
A1: Year | B1: Month | C1: Channel | D1: Brand | E1: Weight range | F1: Units (in 1000) | G1: Units clean | H1: Value (in 1000 rub) | I1: Value clean | J1: Volume (in 1000 kg) | K1: Volume clean | L1: Number of stores
A2: 2020 | B2: 1 | C2: Hypermarkets | D2: Green | E2: 200-249G | F2: 16.3202 | H2: 936.803413 | I2: =VALUE(SUBSTITUTE(H2,".",",")) -> 936.80341 | J2: 866417 | L2: 477
A3: 2020 | B3: 1 | C3: Hypermarkets | D3: Green | E3: 350-399G | F3: 87.8634 | H3: 7019.116508 | I3: =VALUE(SUBSTITUTE(H3,".",",")) -> 7019.1165 | J3: 30.7522 | L3: 754
A4: 2020 | B4: 1 | C4: Hypermarkets | D4: Green | E4: 400-599G | F4: 35.7182 | H4: 4166.453788 | I4: =VALUE(SUBSTITUTE(H4,".",",")) -> 4166.4538 | J4: 17.8592 | L4: 629
A5: 2020 | B5: 1 | C5: Hypermarkets | D5: Green | E5: 600-899G | F5: 0.358 | H5: 66.38769 | I5: =VALUE(SUBSTITUTE(H5,".",",")) -> 66.38769 | J5: 0.2685 | L5: 29
A6: 2020 | B6: 1 | C6: Hypermarkets | D6: Blue | E6: 400-599G | F6: 16.8368 | H6: 3227.992656 | I6: =VALUE(SUBSTITUTE(H6,".",",")) -> 3227.9927 | J6: 1989264 | L6: 663
A7: 2020 | B7: 1 | C7: Hypermarkets | D7: Black | E7: 200-249G | F7: 10.0639 | H7: 573.128758 | I7: =VALUE(SUBSTITUTE(H7,".",",")) -> 573.12876 | J7: 455490 | L7: 547
A8: 2020 | B8: 1 | C8: Hypermarkets | D8: Black | E8: 400-599G | F8: 5.1222 | H8: 559.444379 | I8: =VALUE(SUBSTITUTE(H8,".",",")) -> 559.44438 | J8: 2.305 | L8: 325
A9: 2020 | B9: 1 | C9: Hypermarkets | D9: White | E9: <200G | F9: 1079719 | H9: 328.755626 | I9: =VALUE(SUBSTITUTE(H9,".",",")) -> 328.75563 | J9: 0.6274 | L9: 96
A10: 2020 | B10: 1 | C10: Hypermarkets | D10: Red | E10: 350-399G | F10: 1836807 | H10: 253.642919 | I10: =VALUE(SUBSTITUTE(H10,".",",")) -> 253.64292 | J10: 0.6264 | L10: 95
A11: 2020 | B11: 1 | C11: Hypermarkets | D11: Yellow | E11: 350-399G | F11: 2342333 | H11: 200.763102 | I11: =VALUE(SUBSTITUTE(H11,".",",")) -> 200.7631 | J11: 1.0193 | L11: 191
A12: 2020 | B12: 1 | C12: Hypermarkets | D12: Orange | E12: 250-299G | F12: 0.0068 | H12: 2.200698 | I12: =VALUE(SUBSTITUTE(H12,".",",")) -> 2.200698 | J12: 0.0019 | L12: 4
A13: 2020 | B13: 1 | C13: Hypermarkets | D13: Orange | E13: 400-599G | F13: 0.5648 | H13: 71.031833 | I13: =VALUE(SUBSTITUTE(H13,".",",")) -> 71.031833 | J13: 0.2259 | L13: 78
A14: 2020 | B14: 1 | C14: Hypermarkets | D14: Purple | E14: 400-599G | F14: 0.242 | H14: 61.805145 | I14: =VALUE(SUBSTITUTE(H14,".",",")) -> 61.805145 | J14: 0.0968 | L14: 96
A15: 2020 | B15: 1 | C15: Hypermarkets | D15: Pink | E15: <200G | F15: 0.3707 | H15: 56.153614 | I15: =VALUE(SUBSTITUTE(H15,".",",")) -> 56.153614 | J15: 0.0704 | L15: 0
A16: 2020 | B16: 1 | C16: Hypermarkets | D16: Brown | E16: 400-599G | F16: 0.321 | H16: 50.76976 | I16: =VALUE(SUBSTITUTE(H16,".",",")) -> 50.76976 | J16: 0.1284 | L16: 0
A17: 2020 | B17: 1 | C17: Minimarkets | D17: Green | E17: 200-249G | F17: 66.7225 | H17: 4050.03638 | I17: =VALUE(SUBSTITUTE(H17,".",",")) -> 4050.0364 | J17: 14.0117 | L17: 7561
A18: 2020 | B18: 1 | C18: Minimarkets | D18: Green | E18: 300-349G | F18: 0.0013 | H18: 0.134999 | I18: =VALUE(SUBSTITUTE(H18,".",",")) -> 0.134999 | J18: 0.0004 | L18: 1
A19: 2020 | B19: 1 | C19: Minimarkets | D19: Green | E19: 350-399G | F19: 77.9698 | H19: 7036.255168 | I19: =VALUE(SUBSTITUTE(H19,".",",")) -> 7036.2552 | J19: 27.2894 | L19: 8754
A20: 2020 | B20: 1 | C20: Minimarkets | D20: Green | E20: 400-599G | F20: 7.861 | H20: 1087.96951 | I20: =VALUE(SUBSTITUTE(H20,".",",")) -> 1087.9695 | J20: 2704317 | L20: 1426
A21: 2020 | B21: 1 | C21: Minimarkets | D21: Green | E21: 600-899G | F21: 0.6025 | H21: 109.493529 | I21: =VALUE(SUBSTITUTE(H21,".",",")) -> 109.49353 | J21: 0.4518 | L21: 277
A22: 2020 | B22: 1 | C22: Minimarkets | D22: Yellow | E22: 350-399G | F22: 52.7901 | H22: 3000.962605 | I22: =VALUE(SUBSTITUTE(H22,".",",")) -> 3000.9626 | J22: 19.0044 | L22: 5948
A23: 2020 | B23: 1 | C23: Minimarkets | D23: Blue | E23: 400-599G | F23: 14.2126 | H23: 2169.309011 | I23: =VALUE(SUBSTITUTE(H23,".",",")) -> 2169.309 | J23: 1807708 | L23: 1776
A24: 2020 | B24: 1 | C24: Minimarkets | D24: Black | E24: 200-249G | F24: 535538 | H24: 319.951771 | I24: =VALUE(SUBSTITUTE(H24,".",",")) -> 319.95177 | J24: 0.9974 | L24: 1627
A25: 2020 | B25: 1 | C25: Minimarkets | D25: Black | E25: 400-599G | F25: 1530004 | H25: 234.200456 | I25: =VALUE(SUBSTITUTE(H25,".",",")) -> 234.20046 | J25: 0.7239 | L25: 514
A26: 2020 | B26: 1 | C26: Minimarkets | D26: Red | E26: 350-399G | F26: 240697 | H26: 207.232319 | I26: =VALUE(SUBSTITUTE(H26,".",",")) -> 207.23232 | J26: 0.4648 | L26: 355
A27: 2020 | B27: 1 | C27: Minimarkets | D27: White | E27: <200G | F27: 2.0961 | H27: 177.535357 | I27: =VALUE(SUBSTITUTE(H27,".",",")) -> 177.53536 | J27: 0.3773 | L27: 298
A28: 2020 | B28: 1 | C28: Minimarkets | D28: Grey | E28: 350-399G | F28: 0.5244 | H28: 119.596253 | I28: =VALUE(SUBSTITUTE(H28,".",",")) -> 119.59625 | J28: 0.1835 | L28: 71
A29: 2020 | B29: 1 | C29: Minimarkets | D29: Pale | E29: <200G | F29: 0.0022 | H29: 0.930142 | I29: =VALUE(SUBSTITUTE(H29,".",",")) -> 0.930142 | J29: 0.0004 | L29: 2
A30: 2020 | B30: 1 | C30: Minimarkets | D30: Pale | E30: 400-599G | F30: 0.3416 | H30: 108.540446 | I30: =VALUE(SUBSTITUTE(H30,".",",")) -> 108.54045 | J30: 0.1367 | L30: 49
A31: 2020 | B31: 1 | C31: Minimarkets | D31: Pastel | E31: 250-299G | F31: 1.0783 | H31: 51.908766 | I31: =VALUE(SUBSTITUTE(H31,".",",")) -> 51.908766 | J31: 0.302 | L31: 613
A32: 2020 | B32: 1 | C32: Minimarkets | D32: Mat | E32: 400-599G | F32: 0.4799 | H32: 43.137401 | I32: =VALUE(SUBSTITUTE(H32,".",",")) -> 43.137401 | J32: 0.24 | L32: 0
A33: 2020 | B33: 1 | C33: Supermarkets | D33: Green | E33: 200-249G | F33: 173.1694 | H33: 8930.873194 | I33: =VALUE(SUBSTITUTE(H33,".",",")) -> 8930.8732 | J33: 36.3655 | L33: 10568
A34: 2020 | B34: 1 | C34: Supermarkets | D34: Green | E34: 350-399G | F34: 109.4041 | H34: 9457.396412 | I34: =VALUE(SUBSTITUTE(H34,".",",")) -> 9457.3964 | J34: 38.2914 | L34: 8553
A35: 2020 | B35: 1 | C35: Supermarkets | D35: Green | E35: 400-599G | F35: 41.8318 | H35: 4901.080918 | I35: =VALUE(SUBSTITUTE(H35,".",",")) -> 4901.0809 | J35: 20.916 | L35: 2638
A36: 2020 | B36: 1 | C36: Supermarkets | D36: Green | E36: 600-899G | F36: 0.0807 | H36: 15.311662 | I36: =VALUE(SUBSTITUTE(H36,".",",")) -> 15.311662 | J36: 0.0605 | L36: 53
A37: 2020 | B37: 1 | C37: Supermarkets | D37: Blue | E37: 400-599G | F37: 66.1422 | H37: 9564.403796 | I37: =VALUE(SUBSTITUTE(H37,".",",")) -> 9564.4038 | J37: 26.4569 | L37: 5157
A38: 2020 | B38: 1 | C38: Supermarkets | D38: Yellow | E38: 350-399G | F38: 55.3375 | H38: 3197.053251 | I38: =VALUE(SUBSTITUTE(H38,".",",")) -> 3197.0533 | J38: 19.9215 | L38: 6724
A39: 2020 | B39: 1 | C39: Supermarkets | D39: Black | E39: 200-249G | F39: 19.5669 | H39: 1090.341146 | I39: =VALUE(SUBSTITUTE(H39,".",",")) -> 1090.3411 | J39: 1133439 | L39: 3312
A40: 2020 | B40: 1 | C40: Supermarkets | D40: Black | E40: 400-599G | F40: 7.0743 | H40: 918.309789 | I40: =VALUE(SUBSTITUTE(H40,".",",")) -> 918.30979 | J40: 3.1834 | L40: 1018
...

Sheet Сводная таблица 2020

Sheet 2020 raw
A1: Year | B1: Month | C1: Month clean | D1: Channel | E1: Brand | F1: Weight range | G1: Units (in 1000) | H1: Units clean | I1: Value (in 1000 rub) | J1: Value clean | K1: Volume (in 1000 kg) | L1: Volume clean | M1: Number of stores | N1: Number of stores clean
A2: 2020 | B2: 1 | C2: =VALUE(B2) -> 1 | D2: Hypermarkets | E2: Green | F2: 200-249G | G2: 16.3202 | H2: =VALUE(SUBSTITUTE(G2,".",",")) -> 16.3202 | I2: 936.803413 | J2: =VALUE(SUBSTITUTE(I2,".",",")) -> 936.80341 | K2: 3.4272 | L2: =VALUE(SUBSTITUTE(K2,".",",")) -> 3.4272 | M2: 477 | N2: =VALUE(M2) -> 477
A3: 2020 | B3: 1 | C3: =VALUE(B3) -> 1 | D3: Hypermarkets | E3: Green | F3: 350-399G | G3: 87.8634 | H3: =VALUE(SUBSTITUTE(G3,".",",")) -> 87.8634 | I3: 7019.116508 | J3: =VALUE(SUBSTITUTE(I3,".",",")) -> 7019.1165 | K3: 30.7522 | L3: =VALUE(SUBSTITUTE(K3,".",",")) -> 30.7522 | M3: 754 | N3: =VALUE(M3) -> 754
A4: 2020 | B4: 1 | C4: =VALUE(B4) -> 1 | D4: Hypermarkets | E4: Green | F4: 400-599G | G4: 35.7182 | H4: =VALUE(SUBSTITUTE(G4,".",",")) -> 35.7182 | I4: 4166.453788 | J4: =VALUE(SUBSTITUTE(I4,".",",")) -> 4166.4538 | K4: 17.8592 | L4: =VALUE(SUBSTITUTE(K4,".",",")) -> 17.8592 | M4: 629 | N4: =VALUE(M4) -> 629
A5: 2020 | B5: 1 | C5: =VALUE(B5) -> 1 | D5: Hypermarkets | E5: Green | F5: 600-899G | G5: 0.358 | H5: =VALUE(SUBSTITUTE(G5,".",",")) -> 0.358 | I5: 66.38769 | J5: =VALUE(SUBSTITUTE(I5,".",",")) -> 66.38769 | K5: 0.2685 | L5: =VALUE(SUBSTITUTE(K5,".",",")) -> 0.2685 | M5: 29 | N5: =VALUE(M5) -> 29
A6: 2020 | B6: 1 | C6: =VALUE(B6) -> 1 | D6: Hypermarkets | E6: Blue | F6: 400-599G | G6: 16.8368 | H6: =VALUE(SUBSTITUTE(G6,".",",")) -> 16.8368 | I6: 3227.992656 | J6: =VALUE(SUBSTITUTE(I6,".",",")) -> 3227.9927 | K6: 6.7346 | L6: =VALUE(SUBSTITUTE(K6,".",",")) -> 6.7346 | M6: 663 | N6: =VALUE(M6) -> 663
A7: 2020 | B7: 1 | C7: =VALUE(B7) -> 1 | D7: Hypermarkets | E7: Black | F7: 200-249G | G7: 10.0639 | H7: =VALUE(SUBSTITUTE(G7,".",",")) -> 10.0639 | I7: 573.128758 | J7: =VALUE(SUBSTITUTE(I7,".",",")) -> 573.12876 | K7: 2.3147 | L7: =VALUE(SUBSTITUTE(K7,".",",")) -> 2.3147 | M7: 547 | N7: =VALUE(M7) -> 547
A8: 2020 | B8: 1 | C8: =VALUE(B8) -> 1 | D8: Hypermarkets | E8: Black | F8: 400-599G | G8: 5.1222 | H8: =VALUE(SUBSTITUTE(G8,".",",")) -> 5.1222 | I8: 559.444379 | J8: =VALUE(SUBSTITUTE(I8,".",",")) -> 559.44438 | K8: 2.305 | L8: =VALUE(SUBSTITUTE(K8,".",",")) -> 2.305 | M8: 325 | N8: =VALUE(M8) -> 325
A9: 2020 | B9: 1 | C9: =VALUE(B9) -> 1 | D9: Hypermarkets | E9: White | F9: <200G | G9: 3.4856 | H9: =VALUE(SUBSTITUTE(G9,".",",")) -> 3.4856 | I9: 328.755626 | J9: =VALUE(SUBSTITUTE(I9,".",",")) -> 328.75563 | K9: 0.6274 | L9: =VALUE(SUBSTITUTE(K9,".",",")) -> 0.6274 | M9: 96 | N9: =VALUE(M9) -> 96
A10: 2020 | B10: 1 | C10: =VALUE(B10) -> 1 | D10: Hypermarkets | E10: Red | F10: 350-399G | G10: 1.6929 | H10: =VALUE(SUBSTITUTE(G10,".",",")) -> 1.6929 | I10: 253.642919 | J10: =VALUE(SUBSTITUTE(I10,".",",")) -> 253.64292 | K10: 0.6264 | L10: =VALUE(SUBSTITUTE(K10,".",",")) -> 0.6264 | M10: 95 | N10: =VALUE(M10) -> 95
A11: 2020 | B11: 1 | C11: =VALUE(B11) -> 1 | D11: Hypermarkets | E11: Yellow | F11: 350-399G | G11: 2.8313 | H11: =VALUE(SUBSTITUTE(G11,".",",")) -> 2.8313 | I11: 200.763102 | J11: =VALUE(SUBSTITUTE(I11,".",",")) -> 200.7631 | K11: 1.0193 | L11: =VALUE(SUBSTITUTE(K11,".",",")) -> 1.0193 | M11: 191 | N11: =VALUE(M11) -> 191
A12: 2020 | B12: 1 | C12: =VALUE(B12) -> 1 | D12: Hypermarkets | E12: Orange | F12: 250-299G | G12: 0.0068 | H12: =VALUE(SUBSTITUTE(G12,".",",")) -> 0.0068 | I12: 2.200698 | J12: =VALUE(SUBSTITUTE(I12,".",",")) -> 2.200698 | K12: 0.0019 | L12: =VALUE(SUBSTITUTE(K12,".",",")) -> 0.0019 | M12: 4 | N12: =VALUE(M12) -> 4
A13: 2020 | B13: 1 | C13: =VALUE(B13) -> 1 | D13: Hypermarkets | E13: Orange | F13: 400-599G | G13: 0.5648 | H13: =VALUE(SUBSTITUTE(G13,".",",")) -> 0.5648 | I13: 71.031833 | J13: =VALUE(SUBSTITUTE(I13,".",",")) -> 71.031833 | K13: 0.2259 | L13: =VALUE(SUBSTITUTE(K13,".",",")) -> 0.2259 | M13: 78 | N13: =VALUE(M13) -> 78
... A653: 2020 | B653: 12 | C653: =VALUE(B653) -> 12 | D653: Supermarkets | E653: Green | F653: 100-199G | G653: 40.6617 | H653: =VALUE(SUBSTITUTE(G653,".",",")) -> 40.6617 | I653: 2642.1648 | J653: =VALUE(SUBSTITUTE(I653,".",",")) -> 2642.1648 | K653: 8.1324 | L653: =VALUE(SUBSTITUTE(K653,".",",")) -> 8.1324 | M653: 2079 | N653: =VALUE(M653) -> 2079

Sheet Сводная таблица 2020 raw

Sheet 2021
A1: Year | B1: Month | C1: Channel | D1: Brand | E1: Weight range | F1: Units (in 1000) | G1: Value (in rub) | H1: Value (in 1000 rub) | I1: Volume (in 1000 kg) | J1: Number of stores
A2: 2021 | B2: 1 | C2: Hypermarkets | D2: Green | E2: 200-249G | F2: 2076009 | G2: 817789.128 | H2: =VALUE(SUBSTITUTE(G2,".",","))/1000 -> 817.78913 | I2: 1786799 | J2: 545 | L2: =ISNUMBER(G2) -> FALSE
A3: 2021 | B3: 1 | C3: Hypermarkets | D3: Green | E3: 350-399G | F3: 61.6034 | G3: 5598975.814 | H3: =VALUE(SUBSTITUTE(G3,".",","))/1000 -> 5598.9758 | I3: 21.5612 | J3: 798
A4: 2021 | B4: 1 | C4: Hypermarkets | D4: Green | E4: 400-599G | F4: 47.7524 | G4: 4638537.271 | H4: =VALUE(SUBSTITUTE(G4,".",","))/1000 -> 4638.5373 | I4: 23.8763 | J4: 569
A5: 2021 | B5: 1 | C5: Hypermarkets | D5: Green | E5: 600-899G | F5: 0.0017 | G5: 123.992 | H5: =VALUE(SUBSTITUTE(G5,".",","))/1000 -> 0.123992 | I5: 0.0013 | J5: 1
A6: 2021 | B6: 1 | C6: Hypermarkets | D6: Blue | E6: 200-249G | F6: 0.0509 | G6: 5628.921 | H6: =VALUE(SUBSTITUTE(G6,".",","))/1000 -> 5.628921 | I6: 0.0101 | J6: 6
A7: 2021 | B7: 1 | C7: Hypermarkets | D7: Blue | E7: 400-599G | F7: 32.5492 | G7: 5589670.023 | H7: =VALUE(SUBSTITUTE(G7,".",","))/1000 -> 5589.67 | I7: 13.0196 | J7: 658
A8: 2021 | B8: 1 | C8: Hypermarkets | D8: Black | E8: 200-249G | F8: 626452 | G8: 224651.122 | H8: =VALUE(SUBSTITUTE(G8,".",","))/1000 -> 224.65112 | I8: 0.7731 | J8: 366
A9: 2021 | B9: 1 | C9: Hypermarkets | D9: Black | E9: 400-599G | F9: 821067 | G9: 172739.041 | H9: =VALUE(SUBSTITUTE(G9,".",","))/1000 -> 172.73904 | I9: 0.6367 | J9: 281
A10: 2021 | B10: 1 | C10: Hypermarkets | D10: Yellow | E10: 350-399G | F10: 686383 | G10: 295583.894 | H10: =VALUE(SUBSTITUTE(G10,".",","))/1000 -> 295.58389 | I10: 1410204 | J10: 234
A11: 2021 | B11: 1 | C11: Hypermarkets | D11: White | E11: <200G | F11: 2.563 | G11: 286247.337 | H11: =VALUE(SUBSTITUTE(G11,".",","))/1000 -> 286.24734 | I11: 0.4614 | J11: 102
A12: 2021 | B12: 1 | C12: Hypermarkets | D12: Red | E12: 350-399G | F12: 0.9379999999999999 | G12: 144051.522 | H12: =VALUE(SUBSTITUTE(G12,".",","))/1000 -> 144.05152 | I12: 0.347 | J12: 93
A13: 2021 | B13: 1 | C13: Hypermarkets | D13: Orange | E13: 250-299G | F13: 0.0066 | G13: 2099.316 | H13: =VALUE(SUBSTITUTE(G13,".",","))/1000 -> 2.099316 | I13: 0.0018 | J13: 2
A14: 2021 | B14: 1 | C14: Hypermarkets | D14: Orange | E14: 400-599G | F14: 39814 | G14: 128384.194 | H14: =VALUE(SUBSTITUTE(G14,".",","))/1000 -> 128.38419 | I14: 0.4004 | J14: 122
A15: 2021 | B15: 1 | C15: Hypermarkets | D15: Purple | E15: 400-599G | F15: 0.3449 | G15: 72269.303 | H15: =VALUE(SUBSTITUTE(G15,".",","))/1000 -> 72.269303 | I15: 0.1379 | J15: 167
A16: 2021 | B16: 1 | C16: Hypermarkets | D16: Brown | E16: <200G | F16: 0.3859 | G16: 35374.751 | H16: =VALUE(SUBSTITUTE(G16,".",","))/1000 -> 35.374751 | I16: 0.06950000000000001 | J16: 88
A17: 2021 | B17: 1 | C17: Hypermarkets | D17: Brown | E17: 400-599G | F17: 0.0197 | G17: 3081.309 | H17: =VALUE(SUBSTITUTE(G17,".",","))/1000 -> 3.081309 | I17: 0.007900000000000001 | J17: 11
A18: 2021 | B18: 1 | C18: Hypermarkets | D18: Pink | E18: <200G | F18: 0.2111 | G18: 37134.448 | H18: =VALUE(SUBSTITUTE(G18,".",","))/1000 -> 37.134448 | I18: 0.0401 | J18: 0
A19: 2021 | B19: 1 | C19: Hypermarkets | D19: Pink | E19: 350-399G | F19: 0.0011 | G19: 156.283 | H19: =VALUE(SUBSTITUTE(G19,".",","))/1000 -> 0.156283 | I19: 0.0004 | J19: 0
A20: 2021 | B20: 1 | C20: Minimarkets | D20: Green | E20: 200-249G | F20: 60.7356 | G20: 3633450.875 | H20: =VALUE(SUBSTITUTE(G20,".",","))/1000 -> 3633.4509 | I20: 2061765 | J20: 8174
A21: 2021 | B21: 1 | C21: Minimarkets | D21: Green | E21: 350-399G | F21: 53.4502 | G21: 5188030.767999999 | H21: =VALUE(SUBSTITUTE(G21,".",","))/1000 -> 5188.0308 | I21: 18.7075 | J21: 8539
A22: 2021 | B22: 1 | C22: Minimarkets | D22: Green | E22: 400-599G | F22: 1949027 | G22: 698288.024 | H22: =VALUE(SUBSTITUTE(G22,".",","))/1000 -> 698.28802 | I22: 627520 | J22: 791
A23: 2021 | B23: 1 | C23: Minimarkets | D23: Green | E23: 600-899G | F23: 0.2761 | G23: 44558.407 | H23: =VALUE(SUBSTITUTE(G23,".",","))/1000 -> 44.558407 | I23: 0.2071 | J23: 174
A24: 2021 | B24: 1 | C24: Minimarkets | D24: Blue | E24: 200-249G | F24: 0.0109 | G24: 976.688 | H24: =VALUE(SUBSTITUTE(G24,".",","))/1000 -> 0.976688 | I24: 0.0022 | J24: 2
A25: 2021 | B25: 1 | C25: Minimarkets | D25: Blue | E25: 400-599G | F25: 6.601 | G25: 1395983.538 | H25: =VALUE(SUBSTITUTE(G25,".",","))/1000 -> 1395.9835 | I25: 1644720 | J25: 704
A26: 2021 | B26: 1 | C26: Minimarkets | D26: Yellow | E26: 350-399G | F26: 22.0065 | G26: 1012001.19 | H26: =VALUE(SUBSTITUTE(G26,".",","))/1000 -> 1012.0012 | I26: 2674854 | J26: 1738
A27: 2021 | B27: 1 | C27: Minimarkets | D27: Black | E27: 200-249G | F27: 3.368 | G27: 248807.815 | H27: =VALUE(SUBSTITUTE(G27,".",","))/1000 -> 248.80782 | I27: 0.7747000000000001 | J27: 1602
A28: 2021 | B28: 1 | C28: Minimarkets | D28: Black | E28: 400-599G | F28: 0.6442 | G28: 121949.721 | H28: =VALUE(SUBSTITUTE(G28,".",","))/1000 -> 121.94972 | I28: 0.2899 | J28: 498
A29: 2021 | B29: 1 | C29: Minimarkets | D29: White | E29: <200G | F29: 1344825 | G29: 144102.644 | H29: =VALUE(SUBSTITUTE(G29,".",","))/1000 -> 144.10264 | I29: 0.2804 | J29: 254
A30: 2021 | B30: 1 | C30: Minimarkets | D30: Red | E30: 350-399G | F30: 0.9092 | G30: 139276.358 | H30: =VALUE(SUBSTITUTE(G30,".",","))/1000 -> 139.27636 | I30: 0.3364 | J30: 390
A31: 2021 | B31: 1 | C31: Minimarkets | D31: Golden | E31: 350-399G | F31: 0.7546 | G31: 69099.011 | H31: =VALUE(SUBSTITUTE(G31,".",","))/1000 -> 69.099011 | I31: 0.2641 | J31: 222
A32: 2021 | B32: 1 | C32: Minimarkets | D32: Grey | E32: 350-399G | F32: 0.3194 | G32: 68459.95299999999 | H32: =VALUE(SUBSTITUTE(G32,".",","))/1000 -> 68.459953 | I32: 0.1117 | J32: 121
A33: 2021 | B33: 1 | C33: Minimarkets | D33: Vivid | E33: <200G | F33: 0.0203 | G33: 3688.142 | H33: =VALUE(SUBSTITUTE(G33,".",","))/1000 -> 3.688142 | I33: 0.0036 | J33: 0
A34: 2021 | B34: 1 | C34: Minimarkets | D34: Vivid | E34: 350-399G | F34: 0.2341 | G34: 52410.371 | H34: =VALUE(SUBSTITUTE(G34,".",","))/1000 -> 52.410371 | I34: 0.082 | J34: 0
A35: 2021 | B35: 1 | C35: Minimarkets | D35: Orange | E35: 250-299G | F35: 0.0033 | G35: 1317.17 | H35: =VALUE(SUBSTITUTE(G35,".",","))/1000 -> 1.31717 | I35: 0.0009 | J35: 2
A36: 2021 | B36: 1 | C36: Minimarkets | D36: Orange | E36: 400-599G | F36: 0.4005 | G36: 44008.199 | H36: =VALUE(SUBSTITUTE(G36,".",","))/1000 -> 44.008199 | I36: 0.1602 | J36: 280
A37: 2021 | B37: 1 | C37: Supermarkets | D37: Green | E37: 200-249G | F37: 97.1922 | G37: 5815674.717 | H37: =VALUE(SUBSTITUTE(G37,".",","))/1000 -> 5815.6747 | I37: 20.4104 | J37: 11628
A38: 2021 | B38: 1 | C38: Supermarkets | D38: Green | E38: 350-399G | F38: 147.9807 | G38: 13070828.16 | H38: =VALUE(SUBSTITUTE(G38,".",","))/1000 -> 13070.828 | I38: 51.7931 | J38: 15787
A39: 2021 | B39: 1 | C39: Supermarkets | D39: Green | E39: 400-599G | F39: 9.352499999999999 | G39: 1152899.461 | H39: =VALUE(SUBSTITUTE(G39,".",","))/1000 -> 1152.8995 | I39: 1776266 | J39: 796
A40: 2021 | B40: 1 | C40: Supermarkets | D40: Green | E40: 600-899G | F40: 0.0646 | G40: 9090.562 | H40: =VALUE(SUBSTITUTE(G40,".",","))/1000 -> 9.090562 | I40: 0.0485 | J40: 34
...

Sheet Сводная таблица 2021

Sheet 2021 raw
A1: Year | B1: Month | C1: Month clean | D1: Channel | E1: Brand | F1: Brand clean | G1: Weight range | H1: Units (in 1000) | I1: Units clean | J1: Value (in rub) | K1: Value clean | L1: Volume (in 1000 kg) | M1: Volume clean | N1: Number of stores | O1: Number of stores clean
A2: 2021 | B2: 1 | C2: =VALUE(B2) -> 1 | D2: Hypermarkets | E2: Green | F2: =IF(E2="Greennn#!","Green",E2) -> Green | G2: 200-249G | H2: 12.7583 | I2: =VALUE(SUBSTITUTE(H2,".", ",")) -> 12.7583 | J2: 817789.128 | K2: =VALUE(SUBSTITUTE(J2,".",","))/1000 -> 817.78913 | L2: 2.6792 | M2: =VALUE(SUBSTITUTE(L2,".", ",")) -> 2.6792 | N2: 545 | O2: =VALUE(N2) -> 545
A3: 2021 | B3: 1 | C3: =VALUE(B3) -> 1 | D3: Hypermarkets | E3: Greennn#! | F3: =IF(E3="Greennn#!","Green",E3) -> Green | G3: 350-399G | H3: 61.6034 | I3: =VALUE(SUBSTITUTE(H3,".", ",")) -> 61.6034 | J3: 5598975.814 | K3: =VALUE(SUBSTITUTE(J3,".",","))/1000 -> 5598.9758 | L3: 21.5612 | M3: =VALUE(SUBSTITUTE(L3,".", ",")) -> 21.5612 | N3: 798 | O3: =VALUE(N3) -> 798
A4: 2021 | B4: 1 | C4: =VALUE(B4) -> 1 | D4: Hypermarkets | E4: Greennn#! | F4: =IF(E4="Greennn#!","Green",E4) -> Green | G4: 400-599G | H4: 47.7524 | I4: =VALUE(SUBSTITUTE(H4,".", ",")) -> 47.7524 | J4: 4638537.271 | K4: =VALUE(SUBSTITUTE(J4,".",","))/1000 -> 4638.5373 | L4: 23.8763 | M4: =VALUE(SUBSTITUTE(L4,".", ",")) -> 23.8763 | N4: 569 | O4: =VALUE(N4) -> 569
A5: 2021 | B5: 1 | C5: =VALUE(B5) -> 1 | D5: Hypermarkets | E5: Greennn#! | F5: =IF(E5="Greennn#!","Green",E5) -> Green | G5: 600-899G | H5: 0.0017 | I5: =VALUE(SUBSTITUTE(H5,".", ",")) -> 0.0017 | J5: 123.992 | K5: =VALUE(SUBSTITUTE(J5,".",","))/1000 -> 0.123992 | L5: 0.0013 | M5: =VALUE(SUBSTITUTE(L5,".", ",")) -> 0.0013 | N5: 1 | O5: =VALUE(N5) -> 1
A6: 2021 | B6: 1 | C6: =VALUE(B6) -> 1 | D6: Hypermarkets | E6: Blue | F6: =IF(E6="Greennn#!","Green",E6) -> Blue | G6: 200-249G | H6: 0.0509 | I6: =VALUE(SUBSTITUTE(H6,".", ",")) -> 0.0509 | J6: 5628.921 | K6: =VALUE(SUBSTITUTE(J6,".",","))/1000 -> 5.628921 | L6: 0.0101 | M6: =VALUE(SUBSTITUTE(L6,".", ",")) -> 0.0101 | N6: 6 | O6: =VALUE(N6) -> 6
A7: 2021 | B7: 1 | C7: =VALUE(B7) -> 1 | D7: Hypermarkets | E7: Blue | F7: =IF(E7="Greennn#!","Green",E7) -> Blue | G7: 400-599G | H7: 32.5492 | I7: =VALUE(SUBSTITUTE(H7,".", ",")) -> 32.5492 | J7: 5589670.023 | K7: =VALUE(SUBSTITUTE(J7,".",","))/1000 -> 5589.67 | L7: 13.0196 | M7: =VALUE(SUBSTITUTE(L7,".", ",")) -> 13.0196 | N7: 658 | O7: =VALUE(N7) -> 658
A8: 2021 | B8: 1 | C8: =VALUE(B8) -> 1 | D8: Hypermarkets | E8: Black | F8: =IF(E8="Greennn#!","Green",E8) -> Black | G8: 200-249G | H8: 3.3615 | I8: =VALUE(SUBSTITUTE(H8,".", ",")) -> 3.3615 | J8: 224651.122 | K8: =VALUE(SUBSTITUTE(J8,".",","))/1000 -> 224.65112 | L8: 0.7731 | M8: =VALUE(SUBSTITUTE(L8,".", ",")) -> 0.7731 | N8: 366 | O8: =VALUE(N8) -> 366
A9: 2021 | B9: 1 | C9: =VALUE(B9) -> 1 | D9: Hypermarkets | E9: Black | F9: =IF(E9="Greennn#!","Green",E9) -> Black | G9: 400-599G | H9: 1.4148 | I9: =VALUE(SUBSTITUTE(H9,".", ",")) -> 1.4148 | J9: 172739.041 | K9: =VALUE(SUBSTITUTE(J9,".",","))/1000 -> 172.73904 | L9: 0.6367 | M9: =VALUE(SUBSTITUTE(L9,".", ",")) -> 0.6367 | N9: 281 | O9: =VALUE(N9) -> 281
A10: 2021 | B10: 1 | C10: =VALUE(B10) -> 1 | D10: Hypermarkets | E10: Yellow | F10: =IF(E10="Greennn#!","Green",E10) -> Yellow | G10: 350-399G | H10: 4.3779 | I10: =VALUE(SUBSTITUTE(H10,".", ",")) -> 4.3779 | J10: 295583.894 | K10: =VALUE(SUBSTITUTE(J10,".",","))/1000 -> 295.58389 | L10: 1.5761 | M10: =VALUE(SUBSTITUTE(L10,".", ",")) -> 1.5761 | N10: 234 | O10: =VALUE(N10) -> 234
A11: 2021 | B11: 1 | C11: =VALUE(B11) -> 1 | D11: Hypermarkets | E11: White | F11: =IF(E11="Greennn#!","Green",E11) -> White | G11: <200G | H11: 2.563 | I11: =VALUE(SUBSTITUTE(H11,".", ",")) -> 2.563 | J11: 286247.337 | K11: =VALUE(SUBSTITUTE(J11,".",","))/1000 -> 286.24734 | L11: 0.4614 | M11: =VALUE(SUBSTITUTE(L11,".", ",")) -> 0.4614 | N11: 102 | O11: =VALUE(N11) -> 102
A12: 2021 | B12: 1 | C12: =VALUE(B12) -> 1 | D12: Hypermarkets | E12: Red | F12: =IF(E12="Greennn#!","Green",E12) -> Red | G12: 350-399G | H12: 0.9379999999999999 | I12: =VALUE(SUBSTITUTE(H12,".", ",")) -> 0.938 | J12: 144051.522 | K12: =VALUE(SUBSTITUTE(J12,".",","))/1000 -> 144.05152 | L12: 0.347 | M12: =VALUE(SUBSTITUTE(L12,".", ",")) -> 0.347 | N12: 93 | O12: =VALUE(N12) -> 93
A13: 2021 | B13: 1 | C13: =VALUE(B13) -> 1 | D13: Hypermarkets | E13: Orange | F13: =IF(E13="Greennn#!","Green",E13) -> Orange | G13: 250-299G | H13: 0.0066 | I13: =VALUE(SUBSTITUTE(H13,".", ",")) -> 0.0066 | J13: 2099.316 | K13: =VALUE(SUBSTITUTE(J13,".",","))/1000 -> 2.099316 | L13: 0.0018 | M13: =VALUE(SUBSTITUTE(L13,".", ",")) -> 0.0018 | N13: 2 | O13: =VALUE(N13) -> 2
... A676: 2021 | B676: 12 | C676: =VALUE(B676) -> 12 | D676: Supermarkets | E676: Greennn#! | F676: =IF(E676="Greennn#!","Green",E676) -> Green | G676: 100-199G | H676: 25.2956 | I676: =VALUE(SUBSTITUTE(H676,".", ",")) -> 25.2956 | J676: 1721988.6 | K676: =VALUE(SUBSTITUTE(J676,".",","))/1000 -> 1721.9886 | L676: 5.0591 | M676: =VALUE(SUBSTITUTE(L676,".", ",")) -> 5.0591 | N676: 2407 | O676: =VALUE(N676) -> 2407

Sheet Сводная таблица 2021 raw

Sheet 2022 txt
A1: Year | B1: Month | C1: Channel | D1: Brand | E1: Weight range | F1: Units (in 1000) | G1: Value (in 1000 rub) | H1: Value clean | I1: Volume (in 1000 kg) | J1: Number of stores
A2: 2022 | B2: 1 | C2: Hypermarkets | D2: Green | E2: 200-249G | F2: 15.2249 | G2: 899.265493 | H2: =VALUE(SUBSTITUTE(SUBSTITUTE(G2,"+",""),".",",")) -> 899.26549 | I2: 26359 | J2: 536
A3: 2022 | B3: 1 | C3: Hypermarkets | D3: Green | E3: 350-399G | F3: 58.2443 | G3: 5622.580442 | H3: =VALUE(SUBSTITUTE(SUBSTITUTE(G3,"+",""),".",",")) -> 5622.5804 | I3: 20.3855 | J3: 758
A4: 2022 | B4: 1 | C4: Hypermarkets | D4: Green | E4: 400-599G | F4: 38.4102 | G4: 4457.22479 | H4: =VALUE(SUBSTITUTE(SUBSTITUTE(G4,"+",""),".",",")) -> 4457.2248 | I4: 19.2051 | J4: 633
A5: 2022 | B5: 1 | C5: Hypermarkets | D5: Blue | E5: 200-249G | F5: 0.1327 | G5: 15.948333 | H5: =VALUE(SUBSTITUTE(SUBSTITUTE(G5,"+",""),".",",")) -> 15.948333 | I5: 0.0265 | J5: 10
A6: 2022 | B6: 1 | C6: Hypermarkets | D6: Blue | E6: 400-599G | F6: 44.9287 | G6: 7611.563208 | H6: =VALUE(SUBSTITUTE(SUBSTITUTE(G6,"+",""),".",",")) -> 7611.5632 | I6: 17.9715 | J6: 728
A7: 2022 | B7: 1 | C7: Hypermarkets | D7: White | E7: <200G | F7: 2457750 | G7: 307.946992 | H7: =VALUE(SUBSTITUTE(SUBSTITUTE(G7,"+",""),".",",")) -> 307.94699 | I7: 0.5153 | J7: 210
A8: 2022 | B8: 1 | C8: Hypermarkets | D8: Orange | E8: 250-299G | F8: 0.0225 | G8: 6.422605 | H8: =VALUE(SUBSTITUTE(SUBSTITUTE(G8,"+",""),".",",")) -> 6.422605 | I8: 0.0063 | J8: 13
A9: 2022 | B9: 1 | C9: Hypermarkets | D9: Orange | E9: 400-599G | F9: 1349573 | G9: 212.469968 | H9: =VALUE(SUBSTITUTE(SUBSTITUTE(G9,"+",""),".",",")) -> 212.46997 | I9: 0.6237 | J9: 178
A10: 2022 | B10: 1 | C10: Hypermarkets | D10: Red | E10: 350-399G | F10: 1.0881 | G10: 171.236944 | H10: =VALUE(SUBSTITUTE(SUBSTITUTE(G10,"+",""),".",",")) -> 171.23694 | I10: 0.4026 | J10: 39
A11: 2022 | B11: 1 | C11: Hypermarkets | D11: Yellow | E11: 250-299G | F11: 0.0005 | G11: 0.029771 | H11: =VALUE(SUBSTITUTE(SUBSTITUTE(G11,"+",""),".",",")) -> 0.029771 | I11: 0.0001 | J11: 2
A12: 2022 | B12: 1 | C12: Hypermarkets | D12: Yellow | E12: 350-399G | F12: 971913 | G12: 116.992414 | H12: =VALUE(SUBSTITUTE(SUBSTITUTE(G12,"+",""),".",",")) -> 116.99241 | I12: 0.5242 | J12: 155
A13: 2022 | B13: 1 | C13: Hypermarkets | D13: Magenta | E13: 300-349G | F13: 0.8941 | G13: 95.339903 | H13: =VALUE(SUBSTITUTE(SUBSTITUTE(G13,"+",""),".",",")) -> 95.339903 | I13: 0.2861 | J13: 209
A14: 2022 | B14: 1 | C14: Hypermarkets | D14: Purple | E14: 400-599G | F14: 0.1668 | G14: 38.969667 | H14: =VALUE(SUBSTITUTE(SUBSTITUTE(G14,"+",""),".",",")) -> 38.969667 | I14: 0.0667 | J14: 110
A15: 2022 | B15: 1 | C15: Hypermarkets | D15: Pink | E15: <200G | F15: 0.2026 | G15: 34.905171 | H15: =VALUE(SUBSTITUTE(SUBSTITUTE(G15,"+",""),".",",")) -> 34.905171 | I15: 0.0385 | J15: 80
A16: 2022 | B16: 1 | C16: Hypermarkets | D16: Pink | E16: 350-399G | F16: 0.0014 | G16: 0.142028 | H16: =VALUE(SUBSTITUTE(SUBSTITUTE(G16,"+",""),".",",")) -> 0.142028 | I16: 0.0005 | J16: 1
A17: 2022 | B17: 1 | C17: Hypermarkets | D17: Cotton | E17: 400-599G | F17: 0.1902 | G17: 32.450189 | H17: =VALUE(SUBSTITUTE(SUBSTITUTE(G17,"+",""),".",",")) -> 32.450189 | I17: 0.0865 | J17: 0
A18: 2022 | B18: 1 | C18: Minimarkets | D18: Green | E18: 200-249G | F18: 88.4917 | G18: 4389.809554 | H18: =VALUE(SUBSTITUTE(SUBSTITUTE(G18,"+",""),".",",")) -> 4389.8096 | I18: 18.5833 | J18: 9100
A19: 2022 | B19: 1 | C19: Minimarkets | D19: Green | E19: 350-399G | F19: 57.6908 | G19: 5967.119432 | H19: =VALUE(SUBSTITUTE(SUBSTITUTE(G19,"+",""),".",",")) -> 5967.1194 | I19: 20.1918 | J19: 9322
A20: 2022 | B20: 1 | C20: Minimarkets | D20: Green | E20: 400-599G | F20: 2.834 | G20: 485.822233 | H20: =VALUE(SUBSTITUTE(SUBSTITUTE(G20,"+",""),".",",")) -> 485.82223 | I20: 829468 | J20: 721
A21: 2022 | B21: 1 | C21: Minimarkets | D21: Green | E21: 600-899G | F21: 0.2856 | G21: 46.13722 | H21: =VALUE(SUBSTITUTE(SUBSTITUTE(G21,"+",""),".",",")) -> 46.13722 | I21: 0.2142 | J21: 163
A22: 2022 | B22: 1 | C22: Minimarkets | D22: Blue | E22: 200-249G | F22: 0.0974 | G22: 14.795735 | H22: =VALUE(SUBSTITUTE(SUBSTITUTE(G22,"+",""),".",",")) -> 14.795735 | I22: 0.0195 | J22: 24
A23: 2022 | B23: 1 | C23: Minimarkets | D23: Blue | E23: 400-599G | F23: 8.1112 | G23: 1609.072208 | H23: =VALUE(SUBSTITUTE(SUBSTITUTE(G23,"+",""),".",",")) -> 1609.0722 | I23: 199119 | J23: 1351
A24: 2022 | B24: 1 | C24: Minimarkets | D24: Yellow | E24: 250-299G | F24: 0.6235 | G24: 38.73859 | H24: =VALUE(SUBSTITUTE(SUBSTITUTE(G24,"+",""),".",",")) -> 38.73859 | I24: 0.1621 | J24: 128
A25: 2022 | B25: 1 | C25: Minimarkets | D25: Yellow | E25: 350-399G | F25: 2599006 | G25: 701.603394 | H25: =VALUE(SUBSTITUTE(SUBSTITUTE(G25,"+",""),".",",")) -> 701.60339 | I25: 345612 | J25: 1386
A26: 2022 | B26: 1 | C26: Minimarkets | D26: White | E26: <200G | F26: 8.1162 | G26: 700.442242 | H26: =VALUE(SUBSTITUTE(SUBSTITUTE(G26,"+",""),".",",")) -> 700.44224 | I26: 989444 | J26: 2897
A27: 2022 | B27: 1 | C27: Minimarkets | D27: Snow | E27: 350-399G | F27: 941323 | G27: 193.181003 | H27: =VALUE(SUBSTITUTE(SUBSTITUTE(G27,"+",""),".",",")) -> 193.181 | I27: 1339346 | J27: 435
A28: 2022 | B28: 1 | C28: Minimarkets | D28: Rosy | E28: 350-399G | F28: 60664 | G28: 164.704934 | H28: =VALUE(SUBSTITUTE(SUBSTITUTE(G28,"+",""),".",",")) -> 164.70493 | I28: 0.8496 | J28: 769
A29: 2022 | B29: 1 | C29: Minimarkets | D29: Rosy | E29: 400-599G | F29: 0.1416 | G29: 12.006769 | H29: =VALUE(SUBSTITUTE(SUBSTITUTE(G29,"+",""),".",",")) -> 12.006769 | I29: 0.0694 | J29: 56
A30: 2022 | B30: 1 | C30: Minimarkets | D30: Lilac | E30: 400-599G | F30: 1.1685 | G30: 135.056441 | H30: =VALUE(SUBSTITUTE(SUBSTITUTE(G30,"+",""),".",",")) -> 135.05644 | I30: 0.4674 | J30: 0
A31: 2022 | B31: 1 | C31: Minimarkets | D31: Orange | E31: 250-299G | F31: 0.0036 | G31: 1.59307 | H31: =VALUE(SUBSTITUTE(SUBSTITUTE(G31,"+",""),".",",")) -> 1.59307 | I31: 0.001 | J31: 0
A32: 2022 | B32: 1 | C32: Minimarkets | D32: Orange | E32: 300-349G | F32: 0.0031 | G32: 0.95189 | H32: =VALUE(SUBSTITUTE(SUBSTITUTE(G32,"+",""),".",",")) -> 0.95189 | I32: 0.0009 | J32: 0
A33: 2022 | B33: 1 | C33: Minimarkets | D33: Orange | E33: 400-599G | F33: 0.871 | G33: 127.584278 | H33: =VALUE(SUBSTITUTE(SUBSTITUTE(G33,"+",""),".",",")) -> 127.58428 | I33: 0.3483 | J33: 0
A34: 2022 | B34: 1 | C34: Minimarkets | D34: Black | E34: 200-249G | F34: 623836 | G34: 98.695255 | H34: =VALUE(SUBSTITUTE(SUBSTITUTE(G34,"+",""),".",",")) -> 98.695255 | I34: 0.313 | J34: 422
A35: 2022 | B35: 1 | C35: Minimarkets | D35: Black | E35: 400-599G | F35: 0.0795 | G35: 7.20621 | H35: =VALUE(SUBSTITUTE(SUBSTITUTE(G35,"+",""),".",",")) -> 7.20621 | I35: 0.0358 | J35: 97
A36: 2022 | B36: 1 | C36: Minimarkets | D36: Magenta | E36: 300-349G | F36: 1.0835 | G36: 96.79121 | H36: =VALUE(SUBSTITUTE(SUBSTITUTE(G36,"+",""),".",",")) -> 96.79121 | I36: 0.3467 | J36: 921
A37: 2022 | B37: 1 | C37: Supermarkets | D37: Green | E37: 200-249G | F37: 200.7302 | G37: 10271.13988 | H37: =VALUE(SUBSTITUTE(SUBSTITUTE(G37,"+",""),".",",")) -> 10271.14 | I37: 42.1534 | J37: 17167
A38: 2022 | B38: 1 | C38: Supermarkets | D38: Green | E38: 350-399G | F38: 159.5171 | G38: 14567.6979 | H38: =VALUE(SUBSTITUTE(SUBSTITUTE(G38,"+",""),".",",")) -> 14567.698 | I38: 55.8309 | J38: 17397
A39: 2022 | B39: 1 | C39: Supermarkets | D39: Green | E39: 400-599G | F39: 2670533 | G39: 1323.619549 | H39: =VALUE(SUBSTITUTE(SUBSTITUTE(G39,"+",""),".",",")) -> 1323.6195 | I39: 2814651 | J39: 729
A40: 2022 | B40: 1 | C40: Supermarkets | D40: Green | E40: 600-899G | F40: 0.0087 | G40: 1.791126 | H40: =VALUE(SUBSTITUTE(SUBSTITUTE(G40,"+",""),".",",")) -> 1.791126 | I40: 0.0065 | J40: 3
...

Sheet Сводная таблица 2022 txt

Sheet 2022 xlsx
A1: Date | B1: Year | C1: MonthNum | D1: WeekDayNum | E1: WeekYearNum | F1: MonthDayNum
A2: 44562 | B2: =YEAR(A2) -> 2022 | C2: =MONTH(A2) -> 1 | D2: =WEEKDAY(A2) -> 7 | E2: =WEEKNUM(A2) -> 1 | F2: =DAY(A2) -> 1
A3: 44563 | B3: =YEAR(A3) -> 2022 | C3: =MONTH(A3) -> 1 | D3: =WEEKDAY(A3) -> 1 | E3: =WEEKNUM(A3) -> 2 | F3: =DAY(A3) -> 2
A4: 44564 | B4: =YEAR(A4) -> 2022 | C4: =MONTH(A4) -> 1 | D4: =WEEKDAY(A4) -> 2 | E4: =WEEKNUM(A4) -> 2 | F4: =DAY(A4) -> 3
A5: 44565 | B5: =YEAR(A5) -> 2022 | C5: =MONTH(A5) -> 1 | D5: =WEEKDAY(A5) -> 3 | E5: =WEEKNUM(A5) -> 2 | F5: =DAY(A5) -> 4
A6: 44566 | B6: =YEAR(A6) -> 2022 | C6: =MONTH(A6) -> 1 | D6: =WEEKDAY(A6) -> 4 | E6: =WEEKNUM(A6) -> 2 | F6: =DAY(A6) -> 5
A7: 44567 | B7: =YEAR(A7) -> 2022 | C7: =MONTH(A7) -> 1 | D7: =WEEKDAY(A7) -> 5 | E7: =WEEKNUM(A7) -> 2 | F7: =DAY(A7) -> 6
A8: 44568 | B8: =YEAR(A8) -> 2022 | C8: =MONTH(A8) -> 1 | D8: =WEEKDAY(A8) -> 6 | E8: =WEEKNUM(A8) -> 2 | F8: =DAY(A8) -> 7
A9: 44569 | B9: =YEAR(A9) -> 2022 | C9: =MONTH(A9) -> 1 | D9: =WEEKDAY(A9) -> 7 | E9: =WEEKNUM(A9) -> 2 | F9: =DAY(A9) -> 8
A10: 44570 | B10: =YEAR(A10) -> 2022 | C10: =MONTH(A10) -> 1 | D10: =WEEKDAY(A10) -> 1 | E10: =WEEKNUM(A10) -> 3 | F10: =DAY(A10) -> 9
A11: 44571 | B11: =YEAR(A11) -> 2022 | C11: =MONTH(A11) -> 1 | D11: =WEEKDAY(A11) -> 2 | E11: =WEEKNUM(A11) -> 3 | F11: =DAY(A11) -> 10
A12: 44572 | B12: =YEAR(A12) -> 2022 | C12: =MONTH(A12) -> 1 | D12: =WEEKDAY(A12) -> 3 | E12: =WEEKNUM(A12) -> 3 | F12: =DAY(A12) -> 11
A13: 44573 | B13: =YEAR(A13) -> 2022 | C13: =MONTH(A13) -> 1 | D13: =WEEKDAY(A13) -> 4 | E13: =WEEKNUM(A13) -> 3 | F13: =DAY(A13) -> 12
... A366: 44926 | B366: =YEAR(A366) -> 2022 | C366: =MONTH(A366) -> 12 | D366: =WEEKDAY(A366) -> 7 | E366: =WEEKNUM(A366) -> 53 | F366: =DAY(A366) -> 31

Sheet 2022 raw
A1: Year | B1: Month | C1: Month clean | D1: Channel | E1: Brand | F1: Weight range | G1: Units (in 1000) | H1: Units clean | I1: Value (in 1000 rub) | J1: Value clean | K1: Volume (in 1000 kg) | L1: Volume clean | M1: Number of stores | N1: Number of stores clean
A2: 2022 | B2: 1 | C2: =VALUE(B2) -> 1 | D2: Hypermarkets | E2: Green | F2: 200-249G | G2: 15.2249 | H2: =VALUE(SUBSTITUTE(G2,".", ",")) -> 15.2249 | I2: 899.265493 | J2: =VALUE(SUBSTITUTE(SUBSTITUTE(I2,"+",""),".",",")) -> 899.26549 | K2: 3.1972 | L2: =VALUE(SUBSTITUTE(K2,".", ",")) -> 3.1972 | M2: 536 | N2: =VALUE(M2) -> 536
A3: 2022 | B3: 1 | C3: =VALUE(B3) -> 1 | D3: Hypermarkets | E3: Green | F3: 350-399G | G3: 58.2443 | H3: =VALUE(SUBSTITUTE(G3,".", ",")) -> 58.2443 | I3: 5622.580442 | J3: =VALUE(SUBSTITUTE(SUBSTITUTE(I3,"+",""),".",",")) -> 5622.5804 | K3: 20.3855 | L3: =VALUE(SUBSTITUTE(K3,".", ",")) -> 20.3855 | M3: 758 | N3: =VALUE(M3) -> 758
A4: 2022 | B4: 1 | C4: =VALUE(B4) -> 1 | D4: Hypermarkets | E4: Green | F4: 400-599G | G4: 38.4102 | H4: =VALUE(SUBSTITUTE(G4,".", ",")) -> 38.4102 | I4: 4457.22479 | J4: =VALUE(SUBSTITUTE(SUBSTITUTE(I4,"+",""),".",",")) -> 4457.2248 | K4: 19.2051 | L4: =VALUE(SUBSTITUTE(K4,".", ",")) -> 19.2051 | M4: 633 | N4: =VALUE(M4) -> 633
A5: 2022 | B5: 1 | C5: =VALUE(B5) -> 1 | D5: Hypermarkets | E5: Blue | F5: 200-249G | G5: 0.1327 | H5: =VALUE(SUBSTITUTE(G5,".", ",")) -> 0.1327 | I5: 15.948333 | J5: =VALUE(SUBSTITUTE(SUBSTITUTE(I5,"+",""),".",",")) -> 15.948333 | K5: 0.0265 | L5: =VALUE(SUBSTITUTE(K5,".", ",")) -> 0.0265 | M5: 10 | N5: =VALUE(M5) -> 10
A6: 2022 | B6: 1 | C6: =VALUE(B6) -> 1 | D6: Hypermarkets | E6: Blue | F6: 400-599G | G6: 44.9287 | H6: =VALUE(SUBSTITUTE(G6,".", ",")) -> 44.9287 | I6: 7611.563208 | J6: =VALUE(SUBSTITUTE(SUBSTITUTE(I6,"+",""),".",",")) -> 7611.5632 | K6: 17.9715 | L6: =VALUE(SUBSTITUTE(K6,".", ",")) -> 17.9715 | M6: 728 | N6: =VALUE(M6) -> 728
A7: 2022 | B7: 1 | C7: =VALUE(B7) -> 1 | D7: Hypermarkets | E7: White | F7: <200G | G7: 2.8629 | H7: =VALUE(SUBSTITUTE(G7,".", ",")) -> 2.8629 | I7: 307.946992 | J7: =VALUE(SUBSTITUTE(SUBSTITUTE(I7,"+",""),".",",")) -> 307.94699 | K7: 0.5153 | L7: =VALUE(SUBSTITUTE(K7,".", ",")) -> 0.5153 | M7: 210 | N7: =VALUE(M7) -> 210
A8: 2022 | B8: 1 | C8: =VALUE(B8) -> 1 | D8: Hypermarkets | E8: Orange | F8: 250-299G | G8: 0.0225 | H8: =VALUE(SUBSTITUTE(G8,".", ",")) -> 0.0225 | I8: 6.422605 | J8: =VALUE(SUBSTITUTE(SUBSTITUTE(I8,"+",""),".",",")) -> 6.422605 | K8: 0.0063 | L8: =VALUE(SUBSTITUTE(K8,".", ",")) -> 0.0063 | M8: 13 | N8: =VALUE(M8) -> 13
A9: 2022 | B9: 1 | C9: =VALUE(B9) -> 1 | D9: Hypermarkets | E9: Orange | F9: 400-599G | G9: 1.5595 | H9: =VALUE(SUBSTITUTE(G9,".", ",")) -> 1.5595 | I9: 212.469968 | J9: =VALUE(SUBSTITUTE(SUBSTITUTE(I9,"+",""),".",",")) -> 212.46997 | K9: 0.6237 | L9: =VALUE(SUBSTITUTE(K9,".", ",")) -> 0.6237 | M9: 178 | N9: =VALUE(M9) -> 178
A10: 2022 | B10: 1 | C10: =VALUE(B10) -> 1 | D10: Hypermarkets | E10: Red | F10: 350-399G | G10: 1.0881 | H10: =VALUE(SUBSTITUTE(G10,".", ",")) -> 1.0881 | I10: 171.236944 | J10: =VALUE(SUBSTITUTE(SUBSTITUTE(I10,"+",""),".",",")) -> 171.23694 | K10: 0.4026 | L10: =VALUE(SUBSTITUTE(K10,".", ",")) -> 0.4026 | M10: 39 | N10: =VALUE(M10) -> 39
A11: 2022 | B11: 1 | C11: =VALUE(B11) -> 1 | D11: Hypermarkets | E11: Yellow | F11: 250-299G | G11: 0.0005 | H11: =VALUE(SUBSTITUTE(G11,".", ",")) -> 0.0005 | I11: 0.029771 | J11: =VALUE(SUBSTITUTE(SUBSTITUTE(I11,"+",""),".",",")) -> 0.029771 | K11: 0.0001 | L11: =VALUE(SUBSTITUTE(K11,".", ",")) -> 0.0001 | M11: 2 | N11: =VALUE(M11) -> 2
A12: 2022 | B12: 1 | C12: =VALUE(B12) -> 1 | D12: Hypermarkets | E12: Yellow | F12: 350-399G | G12: 1.4561 | H12: =VALUE(SUBSTITUTE(G12,".", ",")) -> 1.4561 | I12: 116.992414 | J12: =VALUE(SUBSTITUTE(SUBSTITUTE(I12,"+",""),".",",")) -> 116.99241 | K12: 0.5242 | L12: =VALUE(SUBSTITUTE(K12,".", ",")) -> 0.5242 | M12: 155 | N12: =VALUE(M12) -> 155
A13: 2022 | B13: 1 | C13: =VALUE(B13) -> 1 | D13: Hypermarkets | E13: Magenta | F13: 300-349G | G13: 0.8941 | H13: =VALUE(SUBSTITUTE(G13,".", ",")) -> 0.8941 | I13: 95.339903 | J13: =VALUE(SUBSTITUTE(SUBSTITUTE(I13,"+",""),".",",")) -> 95.339903 | K13: 0.2861 | L13: =VALUE(SUBSTITUTE(K13,".", ",")) -> 0.2861 | M13: 209 | N13: =VALUE(M13) -> 209
... A682: 2022 | B682: 12 | C682: =VALUE(B682) -> 12 | D682: Supermarkets | E682: Green | F682: 100-199G | G682: 2.5092 | H682: =VALUE(SUBSTITUTE(G682,".", ",")) -> 2.5092 | I682: 223.1901+ | J682: =VALUE(SUBSTITUTE(SUBSTITUTE(I682,"+",""),".",",")) -> 223.1901 | K682: 0.5018 | L682: =VALUE(SUBSTITUTE(K682,".", ",")) -> 0.5018 | M682: 514 | N682: =VALUE(M682) -> 514

Sheet Сводная таблица 2022 raw

Sheet База данных
A1: Year | B1: Month | C1: Channel | D1: Brand | E1: Weight range | F1: Units (in 1000) | G1: Value (in 1000 rub) | H1: Volume (in 1000 kg) | I1: Number of stores
A2: 2020 | B2: 1 | C2: Hypermarkets | D2: Green | E2: 200-249G | F2: 16.3202 | G2: 936.80341 | H2: 3.4272 | I2: 477
A3: 2020 | B3: 1 | C3: Hypermarkets | D3: Green | E3: 350-399G | F3: 87.8634 | G3: 7019.1165 | H3: 30.7522 | I3: 754
A4: 2020 | B4: 1 | C4: Hypermarkets | D4: Green | E4: 400-599G | F4: 35.7182 | G4: 4166.4538 | H4: 17.8592 | I4: 629
A5: 2020 | B5: 1 | C5: Hypermarkets | D5: Green | E5: 600-899G | F5: 0.358 | G5: 66.38769 | H5: 0.2685 | I5: 29
A6: 2020 | B6: 1 | C6: Hypermarkets | D6: Blue | E6: 400-599G | F6: 16.8368 | G6: 3227.9927 | H6: 6.7346 | I6: 663
A7: 2020 | B7: 1 | C7: Hypermarkets | D7: Black | E7: 200-249G | F7: 10.0639 | G7: 573.12876 | H7: 2.3147 | I7: 547
A8: 2020 | B8: 1 | C8: Hypermarkets | D8: Black | E8: 400-599G | F8: 5.1222 | G8: 559.44438 | H8: 2.305 | I8: 325
A9: 2020 | B9: 1 | C9: Hypermarkets | D9: White | E9: <200G | F9: 3.4856 | G9: 328.75563 | H9: 0.6274 | I9: 96
A10: 2020 | B10: 1 | C10: Hypermarkets | D10: Red | E10: 350-399G | F10: 1.6929 | G10: 253.64292 | H10: 0.6264 | I10: 95
A11: 2020 | B11: 1 | C11: Hypermarkets | D11: Yellow | E11: 350-399G | F11: 2.8313 | G11: 200.7631 | H11: 1.0193 | I11: 191
A12: 2020 | B12: 1 | C12: Hypermarkets | D12: Orange | E12: 250-299G | F12: 0.0068 | G12: 2.200698 | H12: 0.0019 | I12: 4
A13: 2020 | B13: 1 | C13: Hypermarkets | D13: Orange | E13: 400-599G | F13: 0.5648 | G13: 71.031833 | H13: 0.2259 | I13: 78
... A2009: 2022 | B2009: 12 | C2009: Supermarkets | D2009: Green | E2009: 100-199G | F2009: 2.5092 | G2009: 223.1901 | H2009: 0.5018 | I2009: 514

Sheet Сводная таблица База данных

Sheet Контроль качества
A1: Тип проблемы | B1: Где обнаружена | C1: Что обнаружено | D1: Решение
A2: Лишние данные | B2: 2020, Year | C2: Исходный CSV содержит данные за 2019 и 2020 годы, хотя для анализа нужен только 2020 год | D2: Исключить все строки за 2019 год
A3: Технические / ошибочные строки | B3: 2020 | C3: 16 строк без Month, Channel и Brand; числовые показатели имеют искусственное значение 100000 | D3: Исключить 16 строк из анализа
A4: Некорректная категория | B4: 2020, Weight range | C4: Обнаружены значения <200G и 100-199G, которые потенциально пересекаются | D4: Не изменять без подтверждения методологии; учитывать как категории исходных данных
A5: Неверный тип данных | B5: 2020, Month | C5: После импорта значения месяца распознаны как текст, из-за чего нарушалась сортировка 1–12 | D5: Преобразовать Month в числовой формат
A6: Неверный тип данных | B6: 2020, Units / Value / Volume / Number of stores | C6: Часть числовых значений при импорте Google Sheets была некорректно распознана как даты/текст | D6: Восстановить исходные значения и привести показатели к числовому формату
A7: Опечатка в категории | B7: 2021, Brand | C7: Значения Green и Greennn#! относятся к одному бренду | D7: Заменить Greennn#! на Green
A8: Неверная размерность показателя | B8: 2021, Value | C8: В 2021 значения указаны в рублях, тогда как в остальных данных Value указан в тыс. руб. | D8: Разделить значения 2021 на 1000 и привести показатель к Value (in 1000 rub)
A9: Неверный тип данных | B9: 2021, Month | C9: После импорта значения месяца распознаны как текст, из-за чего нарушалась сортировка месяцев 1–12 | D9: Преобразовать Month в числовой формат
A10: Неверный тип данных | B10: 2021, Units / Volume / Number of stores | C10: При импорте часть числовых значений Google Sheets некорректно распознавалась как даты или текст | D10: Повторно импортировать данные без автоматического преобразования и привести показатели к числовому формату
A11: Влияние ошибки на результат | B11: 2021, Brand Green | C11: Из-за Greennn#! почти все наблюдения Green за 2021 год не учитывались как бренд Green, что искажало расчёт динамики | D11: После исправления категории повторно рассчитать показатели Green
A12: Контроль после очистки | B12: 2021 | C12: После исправлений проверены 675 строк, 12 месяцев и итоговые значения основных показателей | D12: Проверить данные сводной таблицей по месяцам; итог Value = 792 958,3002 тыс. руб.
A13: Неверный тип данных | B13: 2022, Month | C13: После импорта значения месяца распознаны как текст, из-за чего нарушалась сортировка месяцев 1–12 | D13: Преобразовать Month в числовой формат
A14: Неверный тип данных | B14: 2022, Units / Volume / Number of stores | C14: После импорта числовые значения распознаны как текст, из-за чего при суммировании получался 0 | D14: Привести значения к числовому формату
A15: Лишние символы / неверный тип данных | B15: 2022, Value | C15: Значения содержат лишний символ + и распознаются как текст; при суммировании получался 0 | D15: Удалить + и преобразовать значения в числовой формат
A16: Контроль после очистки | B16: 2022 | C16: После исправлений проверены 681 строка, 12 месяцев и итоговые значения основных показателей | D16: Проверить данные сводной таблицей по месяцам; итог Value = 824 990,9825 тыс. руб.
A17: Контроль объединённой базы | B17: 2020–2022 | C17: После объединения получено 2008 строк; количество строк и годовые суммы продаж совпадают с результатами контроля каждого года | D17: Сверить количество строк и Value по годам с очищенными исходными данными

Sheet Пересчёт метрик
A1: Показатель | B1: Green | C1: Рынок
A2: FY 2021 | B2: ='Сводная таблица База данных'!C15 -> 522684.06 | C2: ='Сводная таблица База данных'!I15 -> 792958.3
A3: FY 2022 | B3: ='Сводная таблица База данных'!D15 -> 500728.41 | C3: ='Сводная таблица База данных'!J15 -> 824990.98
A4: FY динамика, % | B4: =B3/B2-1 -> -0.04200558 | C4: =C3/C2-1 -> 0.040396427
A5: L3M 2021 | B5: =SUM('Сводная таблица База данных'!C12:C14) -> 135235.6 | C5: =SUM('Сводная таблица База данных'!I12:I14) -> 214912.01
A6: L3M 2022 | B6: =SUM('Сводная таблица База данных'!D12:D14) -> 114267.3 | C6: =SUM('Сводная таблица База данных'!J12:J14) -> 201234.05
A7: L3M динамика, % | B7: =B6/B5-1 -> -0.15505017 | C7: =C6/C5-1 -> -0.063644461
A8: Декабрь 2021 | B8: ='Сводная таблица База данных'!C14 -> 43809.543 | C8: ='Сводная таблица База данных'!I14 -> 68524.721
A9: Декабрь 2022 | B9: ='Сводная таблица База данных'!D14 -> 35212.074 | C9: ='Сводная таблица База данных'!J14 -> 63387.249
A10: Декабрь динамика, % | B10: =B9/B8-1 -> -0.19624649 | C10: =C9/C8-1 -> -0.074972531
D12: Результат проверки качества данных: При проверке данных за 2021 год была обнаружена ошибка в наименовании бренда: большая часть наблюдений Green была записана как Greennn#!. Из-за этого продажи Green за 2021 год существенно занижались, что приводило к неверной оценке динамики бренда. После исправления категории и повторного расчёта продажи Green за 2021 год составили 522 684,06 тыс. руб., а динамика 2022/2021 — −4,20%. При этом рынок за тот же период вырос на 4,04%. Таким образом, после проверки качества вывод изменился: Green не демонстрирует рост, а, напротив, показывает динамику хуже рынка. За последние три месяца снижение Green составило −15,51% против −6,36% по рынку, а в декабре — −19,62% против −7,50%. Это показывает усиление негативной динамики Green к концу 2022 года.

Sheet ТОП-5 по каналам
P4: Место | Q4: Гипермаркеты | R4: Продажи, тыс. руб. | S4: Минимаркеты | T4: Продажи, тыс. руб. 2 | U4: Супермаркеты | V4: Продажи, тыс. руб. 3
P5: 1 | Q5: =G2 -> Green | R5: =H2 -> 118318.65 | S5: =J2 -> Green | T5: =K2 -> 110107.78 | U5: =M2 -> Green | V5: =N2 -> 272301.98
P6: 2 | Q6: =G3 -> Blue | R6: =H3 -> 87186.432 | S6: =J3 -> Blue | T6: =K3 -> 28378.209 | U6: =M3 -> Blue | V6: =N3 -> 105801.86
P7: 3 | Q7: =G4 -> Orange | R7: =H4 -> 4990.2211 | S7: =J4 -> Yellow | T7: =K4 -> 7788.6439 | U7: =M4 -> Yellow | V7: =N4 -> 21230.259
P8: 4 | Q8: =G5 -> White | R8: =H5 -> 3412.6708 | S8: =J5 -> White | T8: =K5 -> 4424.6321 | U8: =M5 -> Pearl | V8: =N5 -> 10974.993
P9: 5 | Q9: =G6 -> Yellow | R9: =H6 -> 2041.4898 | S9: =J6 -> Orange | T9: =K6 -> 1750.1118 | U9: =M6 -> Orange | V9: =N6 -> 8740.2883

Sheet Доля рынка
C1: Доля рынка, %
C2: =B2/$B$16 -> 0.29494779
C3: =B3/$B$16 -> 0.0016057278
C4: =B4/$B$16 -> 0.0041411913
C5: =B5/$B$16 -> 0.56518123
C6: =B6/$B$16 -> 0.00056559714
C7: =B7/$B$16 -> 0.00097819048
C8: =B8/$B$16 -> 0.024462358
C9: =B9/$B$16 -> 0.031195455
C10: =B10/$B$16 -> 0.0063815463
C11: =B11/$B$16 -> 0.0015299796
C12: =B12/$B$16 -> 0.010864373
C13: =B13/$B$16 -> 0.00087803174
... C15: =B15/$B$16 -> 0.054980844
C16: =SUM(C2:C15) -> 1

Sheet Динамика доли
F20: Month | G20: 2021 Blue | H20: 2021 Green | I20: 2021 Orange | J20: 2021 Pearl | K20: 2021 Yellow | L20: 2022 Blue | M20: 2022 Green | N20: 2022 Orange | O20: 2022 Pearl | P20: 2022 Yellow
F21: 1 | G21: =G4/B3 -> 0.30597736 | H21: =H4/B3 -> 0.5368316 | I21: =I4/B3 -> 0 | J21: =0 -> 0 | K21: =J4/B3 -> 0.07826802 | L21: =L4/C3 -> 0.35071031 | M21: =M4/C3 -> 0.56100438 | N21: =N4/C3 -> 0.0092250376 | O21: =O4/C3 -> 0 | P21: =P4/C3 -> 0.047148928
F22: 2 | G22: =G5/B4 -> 0.23372137 | H22: =H5/B4 -> 0.60677755 | I22: =I5/B4 -> 0 | J22: =0 -> 0 | K22: =J5/B4 -> 0.075007549 | L22: =L5/C4 -> 0.26540081 | M22: =M5/C4 -> 0.58104121 | N22: =N5/C4 -> 0.031951869 | O22: =O5/C4 -> 0.017357159 | P22: =P5/C4 -> 0.075521053
F23: 3 | G23: =G6/B5 -> 0.29017199 | H23: =H6/B5 -> 0.56058232 | I23: =I6/B5 -> 0 | J23: =0 -> 0 | K23: =J6/B5 -> 0.073600209 | L23: =L6/C5 -> 0.35852033 | M23: =M6/C5 -> 0.50641889 | N23: =N6/C5 -> 0.02701227 | O23: =O6/C5 -> 0.02473016 | P23: =P6/C5 -> 0.05753881
F24: 4 | G24: =G7/B6 -> 0.20337672 | H24: =H7/B6 -> 0.64179513 | I24: =I7/B6 -> 0 | J24: =0 -> 0 | K24: =J7/B6 -> 0.098216056 | L24: =L7/C6 -> 0.27901637 | M24: =M7/C6 -> 0.54767823 | N24: =N7/C6 -> 0.034121772 | O24: =O7/C6 -> 0.02966932 | P24: =P7/C6 -> 0.063276362
F25: 5 | G25: =G8/B7 -> 0.31134277 | H25: =H8/B7 -> 0.44880894 | I25: =I8/B7 -> 0 | J25: =0 -> 0 | K25: =J8/B7 -> 0.063538817 | L25: =L8/C7 -> 0.24838209 | M25: =M8/C7 -> 0.57994856 | N25: =N8/C7 -> 0.038978297 | O25: =O8/C7 -> 0.034031134 | P25: =P8/C7 -> 0.060837607
F26: 6 | G26: =G9/B8 -> 0.22762945 | H26: =H9/B8 -> 0.51958153 | I26: =I9/B8 -> 0 | J26: =0 -> 0 | K26: =J9/B8 -> 0.059019498 | L26: =L9/C8 -> 0.27250426 | M26: =M9/C8 -> 0.58452142 | N26: =N9/C8 -> 0.025328438 | O26: =O9/C8 -> 0.033920872 | P26: =P9/C8 -> 0.044345463
F27: 7 | G27: =G10/B9 -> 0.28417798 | H27: =H10/B9 -> 0.48104461 | I27: =I10/B9 -> 0 | J27: =0 -> 0 | K27: =J10/B9 -> 0.073137846 | L27: =L10/C9 -> 0.27774293 | M27: =M10/C9 -> 0.58430274 | N27: =N10/C9 -> 0.021185518 | O27: =O10/C9 -> 0.030082965 | P27: =P10/C9 -> 0.058483235
F28: 8 | G28: =G11/B10 -> 0.24717621 | H28: =H11/B10 -> 0.58221458 | I28: =I11/B10 -> 0 | J28: =0 -> 0 | K28: =J11/B10 -> 0.049738703 | L28: =L11/C10 -> 0.27579079 | M28: =M11/C10 -> 0.59309155 | N28: =N11/C10 -> 0.020026498 | O28: =O11/C10 -> 0.041769939 | P28: =P11/C10 -> 0.04290725
F29: 9 | G29: =G12/B11 -> 0.25974868 | H29: =H12/B11 -> 0.58304181 | I29: =I12/B11 -> 0 | J29: =0 -> 0 | K29: =J12/B11 -> 0.08713637 | L29: =L12/C11 -> 0.25240845 | M29: =M12/C11 -> 0.58514287 | N29: =N12/C11 -> 0.018842314 | O29: =O12/C11 -> 0.042277646 | P29: =P12/C11 -> 0.071614181
F30: 10 | G30: =G13/B12 -> 0.32542043 | H30: =H13/B12 -> 0.5712506 | I30: =I13/B12 -> 0 | J30: =0 -> 0 | K30: =J13/B12 -> 0.039291192 | L30: =L13/C12 -> 0.26805635 | M30: =M13/C12 -> 0.6198966 | N30: =N13/C12 -> 0.020494632 | O30: =O13/C12 -> 0.036728484 | P30: =P13/C12 -> 0.034874246
F31: 11 | G31: =G14/B13 -> 0.31803038 | H31: =H14/B13 -> 0.56348444 | I31: =I14/B13 -> 0.0054808239 | J31: =0 -> 0 | K31: =J14/B13 -> 0.071499916 | L31: =L14/C13 -> 0.35988786 | M31: =M14/C13 -> 0.50714438 | N31: =N14/C13 -> 0.021027055 | O31: =O14/C13 -> 0.043074622 | P31: =P14/C13 -> 0.050453688
F32: 12 | G32: =G15/B14 -> 0.29375923 | H32: =H15/B14 -> 0.61313016 | I32: =I15/B14 -> 0.0067950353 | J32: =0 -> 0 | K32: =J15/B14 -> 0.052799663 | L32: =L15/C14 -> 0.28925098 | M32: =M15/C14 -> 0.56387991 | N32: =N15/C14 -> 0.025190896 | O32: =O15/C14 -> 0.040165534 | P32: =P15/C14 -> 0.057867329

Sheet Каналы
G3: Channel | H3: Прирост 2021 | I3: Прирост 2022 | J3: Доля 2021 | K3: Доля 2022
G4: Hypermarkets | H4: =C3/B3-1 -> 0.062670318 | I4: =D3/C3-1 -> 0.019732852 | J4: =C3/C$6 -> 0.27275697 | K4: =D3/D$6 -> 0.26733967
G5: Minimarkets | H5: =C4/B4-1 -> -0.1082166 | I5: =D4/C4-1 -> -0.017327539 | J5: =C4/C$6 -> 0.20584829 | K5: =D4/D$6 -> 0.19442727
G6: Supermarkets | H6: =C5/B5-1 -> 0.15405285 | I6: =D5/C5-1 -> 0.073995756 | J6: =C5/C$6 -> 0.52139474 | K6: =D5/D$6 -> 0.53823305

Sheet Офтейк
B1: Channel | C1: Значения
B2: Hypermarkets | D2: Minimarkets | F2: Supermarkets | H2: Итого
A3: Month | B3: SUM из Units (in 1000) | C3: SUM из Number of stores | D3: SUM из Units (in 1000) | E3: SUM из Number of stores | F3: SUM из Units (in 1000) | G3: SUM из Number of stores | H3: SUM из Units (in 1000) | I3: SUM из Number of stores
A4: 1 | B4: 58.2443 | C4: 758 | D4: 57.6908 | E4: 9322 | F4: 159.5171 | G4: 17397 | H4: 275.4522 | I4: 27477
A5: 2 | B5: 47.1109 | C5: 744 | D5: 54.6811 | E5: 8884 | F5: 129.5281 | G5: 16535 | H5: 231.3201 | I5: 26163
A6: 3 | B6: 73.7461 | C6: 710 | D6: 62.9831 | E6: 9221 | F6: 159.762 | G6: 17796 | H6: 296.4912 | I6: 27727
A7: 4 | B7: 54.2457 | C7: 679 | D7: 61.0993 | E7: 8855 | F7: 150.4402 | G7: 17610 | H7: 265.7852 | I7: 27144
A8: 5 | B8: 42.728 | C8: 677 | D8: 62.5334 | E8: 8839 | F8: 139.1166 | G8: 18024 | H8: 244.378 | I8: 27540
A9: 6 | B9: 56.8652 | C9: 681 | D9: 49.5326 | E9: 9047 | F9: 107.7345 | G9: 17303 | H9: 214.1323 | I9: 27031
A10: 7 | B10: 38.0089 | C10: 654 | D10: 59.8725 | E10: 9650 | F10: 154.4919 | G10: 18868 | H10: 252.3733 | I10: 29172
A11: 8 | B11: 30.6216 | C11: 636 | D11: 58.144 | E11: 9622 | F11: 136.4948 | G11: 19290 | H11: 225.2604 | I11: 29548
A12: 9 | B12: 36.8494 | C12: 561 | D12: 53.9114 | E12: 8071 | F12: 101.4127 | G12: 16888 | H12: 192.1735 | I12: 25520
A13: 10 | B13: 65.06 | C13: 624 | D13: 53.1301 | E13: 8665 | F13: 195.5282 | G13: 18126 | H13: 313.7183 | I13: 27415
A14: 11 | B14: 49.6322 | C14: 623 | D14: 33.4998 | E14: 8472 | F14: 109.5556 | G14: 17478 | H14: 192.6876 | I14: 26573
A15: 12 | B15: 26.398 | C15: 596 | D15: 41.9372 | E15: 7912 | F15: 124.5474 | G15: 16029 | H15: 192.8826 | I15: 24537
A16: Итого | B16: 579.5103 | C16: 7943 | D16: 649.0153 | E16: 106560 | F16: 1668.1291 | G16: 211344 | H16: 2896.6547 | I16: 325847
A20: Month | B20: Green Hypermarkets | C20: Green Supermarkets | D20: Green Minimarkets | E20: Blue Hypermarkets | F20: Blue Supermarkets | G20: Blue Minimarkets
A21: 1 | B21: =B4*1000/C4 -> 76.839446 | C21: =F4*1000/G4 -> 9.1692303 | D21: =D4*1000/E4 -> 6.188672 | E21: =L4*1000/M4 -> 61.715247 | F21: =P4*1000/Q4 -> 13.248526 | G21: =N4*1000/O4 -> 6.003849
A22: 2 | B22: =B5*1000/C5 -> 63.321102 | C22: =F5*1000/G5 -> 7.8335712 | D22: =D5*1000/E5 -> 6.155009 | E22: =L5*1000/M5 -> 51.656772 | F22: =P5*1000/Q5 -> 7.3953453 | G22: =N5*1000/O5 -> 7.0578657
A23: 3 | B23: =B6*1000/C6 -> 103.86775 | C23: =F6*1000/G6 -> 8.9774107 | D23: =D6*1000/E6 -> 6.830398 | E23: =L6*1000/M6 -> 66.973333 | F23: =P6*1000/Q6 -> 14.708993 | G23: =N6*1000/O6 -> 6.7161554
A24: 4 | B24: =B7*1000/C7 -> 79.890574 | C24: =F7*1000/G7 -> 8.5428847 | D24: =D7*1000/E7 -> 6.8999774 | E24: =L7*1000/M7 -> 46.02891 | F24: =P7*1000/Q7 -> 9.1964845 | G24: =N7*1000/O7 -> 7.4537563
A25: 5 | B25: =B8*1000/C8 -> 63.113737 | C25: =F8*1000/G8 -> 7.7184088 | D25: =D8*1000/E8 -> 7.0747143 | E25: =L8*1000/M8 -> 52.668413 | F25: =P8*1000/Q8 -> 7.5776845 | G25: =N8*1000/O8 -> 5.911731
A26: 6 | B26: =B9*1000/C9 -> 83.502496 | C26: =F9*1000/G9 -> 6.226348 | D26: =D9*1000/E9 -> 5.4750304 | E26: =L9*1000/M9 -> 42.81195 | F26: =P9*1000/Q9 -> 7.1072443 | G26: =N9*1000/O9 -> 5.8401392
A27: 7 | B27: =B10*1000/C10 -> 58.117584 | C27: =F10*1000/G10 -> 8.1880379 | D27: =D10*1000/E10 -> 6.2044041 | E27: =L10*1000/M10 -> 64.644019 | F27: =P10*1000/Q10 -> 10.226275 | G27: =N10*1000/O10 -> 6.080508
A28: 8 | B28: =B11*1000/C11 -> 48.14717 | C28: =F11*1000/G11 -> 7.0759357 | D28: =D11*1000/E11 -> 6.0428185 | E28: =L11*1000/M11 -> 45.285161 | F28: =P11*1000/Q11 -> 9.2108164 | G28: =N11*1000/O11 -> 5.5799197
A29: 9 | B29: =B12*1000/C12 -> 65.685205 | C29: =F12*1000/G12 -> 6.0050154 | D29: =D12*1000/E12 -> 6.6796432 | E29: =L12*1000/M12 -> 62.648392 | F29: =P12*1000/Q12 -> 8.7423781 | G29: =N12*1000/O12 -> 6.7879087
A30: 10 | B30: =B13*1000/C13 -> 104.26282 | C30: =F13*1000/G13 -> 10.787168 | D30: =D13*1000/E13 -> 6.1315753 | E30: =L13*1000/M13 -> 52.51256 | F30: =P13*1000/Q13 -> 14.363776 | G30: =N13*1000/O13 -> 6.8669983
A31: 11 | B31: =B14*1000/C14 -> 79.666453 | C31: =F14*1000/G14 -> 6.2682 | D31: =D14*1000/E14 -> 3.9541785 | E31: =L14*1000/M14 -> 82.431825 | F31: =P14*1000/Q14 -> 7.8594664 | G31: =N14*1000/O14 -> 6.2617889
A32: 12 | B32: =B15*1000/C15 -> 44.291946 | C32: =F15*1000/G15 -> 7.7701291 | D32: =D15*1000/E15 -> 5.300455 | E32: =L15*1000/M15 -> 67.817236 | F32: =P15*1000/Q15 -> 6 | G32: =N15*1000/O15 -> 5.4837589

Sheet Цена
A1: Month | B1: SUM из Units (in 1000) | C1: SUM из Value (in 1000 rub)
A2: 1 | B2: 58.2443 | C2: 5622.5804
A3: 2 | B3: 47.1109 | C3: 4702.0041
A4: 3 | B4: 73.7461 | C4: 7356.7612
A5: 4 | B5: 54.2457 | C5: 5684.1814
A6: 5 | B6: 42.728 | C6: 4568.3093
A7: 6 | B7: 56.8652 | C7: 5681.4959
A8: 7 | B8: 38.0089 | C8: 4003.4489
A9: 8 | B9: 30.6216 | C9: 3368.8656
A10: 9 | B10: 36.8494 | C10: 3683.3466
A11: 10 | B11: 65.06 | C11: 5995.7105
A12: 11 | B12: 49.6322 | C12: 4540.5663
A13: 12 | B13: 26.398 | C13: 3098.2747
A14: Итого | B14: 579.5103 | C14: 58305.545
A18: Month | B18: Green, руб./шт. | C18: Blue, руб./шт.
A19: 1 | B19: =C2/B2 -> 96.534432 | C19: =G2/F2 -> 169.41428
A20: 2 | B20: =C3/B3 -> 99.807138 | C20: =G3/F3 -> 166.32291
A21: 3 | B21: =C4/B4 -> 99.757969 | C21: =G4/F4 -> 199.54632
A22: 4 | B22: =C5/B5 -> 104.78584 | C22: =G5/F5 -> 216.37316
A23: 5 | B23: =C6/B6 -> 106.91606 | C23: =G6/F6 -> 199.7974
A24: 6 | B24: =C7/B7 -> 99.911649 | C24: =G7/F7 -> 206.03667
A25: 7 | B25: =C8/B8 -> 105.32925 | C25: =G8/F8 -> 178.55071
A26: 8 | B26: =C9/B9 -> 110.01599 | C26: =G9/F9 -> 205.40588
A27: 9 | B27: =C10/B10 -> 99.956759 | C27: =G10/F10 -> 191.90381
A28: 10 | B28: =C11/B11 -> 92.156633 | C28: =G11/F11 -> 205.80063
A29: 11 | B29: =C12/B12 -> 91.484284 | C29: =G12/F12 -> 178.05934
A30: 12 | B30: =C13/B13 -> 117.36778 | C30: =G13/F13 -> 191.52493

Sheet Выводы
A1: 1. TOP-5 брендов по каналам
A2: Во всех трёх каналах продаж лидирующие позиции занимают Green и Blue: Green занимает первое место, Blue — второе. Остальной состав TOP-5 немного различается в зависимости от канала. Таким образом, лидерство Green и Blue устойчиво во всех рассматриваемых каналах продаж.
A3: 2. Доля рынка в Supermarkets, сегмент 350–599G
A4: В 2022 году в канале Supermarkets и сегменте 350–599G рынок сильно концентрирован: Green занимает 56,52%, Blue — 29,49%. Вместе два лидирующих бренда занимают около 86% рынка.
A5: 3. Динамика долей TOP-5
A6: В 2021–2022 годах Green сохраняет лидирующую позицию в сегменте 350–599G канала Supermarkets, а Blue стабильно занимает второе место. Доля Green колеблется по месяцам, но в большинстве месяцев остаётся выше 50%. Остальные бренды имеют существенно меньшие доли рынка.
A7: 4. Динамика каналов продаж
A8: Supermarkets является крупнейшим и наиболее быстро растущим каналом продаж. В 2022 году его продажи выросли на 7,40%, а доля рынка увеличилась с 52,14% до 53,82%. Hypermarkets также показывает положительную динамику (+1,97% в 2022 году), однако растёт медленнее, поэтому его доля немного снизилась. Minimarkets сокращается второй год подряд: в 2021 году продажи снизились на 10,82%, в 2022 году — ещё на 1,73%, а доля канала уменьшилась с 20,58% до 19,44%.
A9: 5. Offtake
A10: В 2022 году наиболее высокий оффтейк Green и Blue наблюдается в канале Hypermarkets. В Supermarkets оффтейк Blue в большинстве месяцев несколько выше, чем у Green, а в Minimarkets показатели двух брендов находятся примерно на сопоставимом уровне. В течение года оффтейк обоих брендов изменяется от месяца к месяцу.
A11: 6. Средняя цена
A12: В 2022 году в канале Hypermarkets средняя цена Blue 400–599G заметно выше средней цены Green 350–399G на протяжении всего рассматриваемого периода. Цены обоих брендов изменяются от месяца к месяцу, однако Blue во все месяцы сохраняет более высокий уровень средней цены.
... A14: В ходе проверки качества данных были обнаружены лишние данные за 2019 год, технические строки с отсутствующими значениями Month, Channel и Brand, некорректное название бренда Greennn#!, различия в размерности показателя Value, а также проблемы с типами данных при импорте. После очистки и приведения данных к единому формату показатели были пересчитаны. Наиболее существенное влияние оказала ошибка в названии бренда Green: значительная часть продаж 2021 года была записана как Greennn#!, из-за чего продажи Green были сильно занижены и динамика 2022 года относительно 2021 года рассчитывалась некорректно. После исправления данных результаты изменились. Это показывает, что проверка качества данных должна выполняться до проведения анализа, поскольку ошибки в исходных данных могут привести к неверным аналитическим выводам и, как следствие, неправильным бизнес-решениям.
